Workbook

Sheet Допущения
A1: VitaGen-AI — ФИНАНСОВАЯ МОДЕЛЬ (2026–2030). Все значения в млн ₽, если не указано иное
A2: Жёлтые ячейки — входные параметры. Рыночные данные атрибутированы на листе «Рынок». Модель сценарная: переключатель в C4.
A4: СЦЕНАРИЙ (0 — пессимистичный, 1 — базовый, 2 — оптимистичный) | C4: 1
A5: Коэффициент к выручке | C5: =IF(C4=0,0.75,IF(C4=1,1,1.3)) -> 1
A6: Коэффициент к расходам | C6: =IF(C4=0,1.12,IF(C4=1,1,0.95)) -> 1
A8: Показатель | B8: Ед. | C8: 2026 | D8: 2027 | E8: 2028 | F8: 2029 | G8: 2030
A10: МОНЕТИЗАЦИЯ (цены)
A11: Подписка клиники (SaaS + аналитика базового модуля) | B11: млн ₽/год | C11: 2.2 | D11: 2.3 | E11: 2.5 | F11: 2.6 | G11: 2.8
A12: Доп. модули ARPU на клинику | B12: млн ₽/год | C12: 0.15 | D12: 0.35 | E12: 0.6 | F12: 0.8 | G12: 1
A13: Матчинг донорство/СМ (за случай) | B13: млн ₽ | C13: 0.18 | D13: 0.18 | E13: 0.18 | F13: 0.18 | G13: 0.18
A14: B2G-аналитика региона (CLBR/CPLB) | B14: млн ₽/год | C14: 4 | D14: 4.5 | E14: 5 | F14: 5.5 | G14: 6
A15: APAC-партнёр (лицензия, Хайнань/АТР) | B15: млн ₽/год | C15: 8 | D15: 8 | E15: 8.5 | F15: 8.5 | G15: 8.5
A17: ОБЪЁМЫ ПРОДАЖ (конец периода, накопительно)
A18: Клиники-абоненты в РФ | B18: шт | C18: 3 | D18: 12 | E18: 32 | F18: 55 | G18: 85
A19: Регионы — контракты B2G | B19: шт | C19: 0 | D19: 1 | E19: 2 | F19: 3 | G19: 5
A20: Случаи матча донорство/СМ | B20: случаев/год | C20: 0 | D20: 8 | E20: 25 | F20: 45 | G20: 70
A21: APAC-партнёры (эквивалент полной загрузки) | B21: FTE-экв. | C21: 0 | D21: 0 | E21: 0 | F21: 1 | G21: 3
A23: РАСХОДЫ (млн ₽, с коэффициентом сценария)
A24: ФОТ с отчислениями (команда) | B24: млн ₽ | C24: 24 | D24: 40 | E24: 62 | F24: 95 | G24: 140
A25: НИОКР: подряды, данные, обучение моделей | B25: млн ₽ | C25: 10 | D25: 12 | E25: 15 | F25: 20 | G25: 28
A26: Маркетинг и продажи (без ФОТ продаж) | B26: млн ₽ | C26: 2 | D26: 5 | E26: 10 | F26: 16 | G26: 24
A27: Инфраструктура / облако / поддержка | B27: млн ₽ | C27: 2 | D27: 4 | E27: 9 | F27: 18 | G27: 30
A28: Административные, юр., бух., аренда | B28: млн ₽ | C28: 4 | D28: 6 | E28: 8 | F28: 11 | G28: 15
A29: Регуляторика РФ (ИИ-МИ) + NMPA (Китай) | B29: млн ₽ | C29: 4.5 | D29: 3.5 | E29: 2.5 | F29: 7 | G29: 8
A31: НАЛОГИ И ИНВЕСТИЦИИ
A32: УСН «доходы» (консервативно; возможен Сколково 0%) | B32: % | C32: 5 | D32: 5 | E32: 5 | F32: 5 | G32: 5
A33: Раунд 1 — Seed (привлечено) | B33: млн ₽ | C33: 35 | D33: 0 | E33: 0 | F33: 0 | G33: 0
A34: Раунд 2 — Series A (привлечено) | B34: млн ₽ | C34: 0 | D34: 45 | E34: 0 | F34: 0 | G34: 0
A35: Гранты (non-dilutive: ФСИ, Сколково, ДЗМ) | B35: млн ₽ | C35: 5 | D35: 8 | E35: 6 | F35: 4 | G35: 2
A37: ПАРАМЕТРЫ ОЦЕНКИ И ВЫХОДА
A38: Pre-money до Раунда 1 (вкл. ИС ~45 млн ₽, оценка лист «ИС_Оценка») | B38: млн ₽ | C38: 110
A39: Pre-money до Раунда 2 | B39: млн ₽ | C39: 280
A40: Ожидаемая EBITDA 2031 (рост к 2030) | B40: млн ₽ | C40: 180
A41: Множитель EBITDA при выходе (стратег. покупатель) | B41: x | C41: 7.5
A42: Ставка дисконтирования для NPV инвестора | B42: % | C42: 0.25

Sheet Рынок
A1: РЫНОК: источники и ключевые данные (собственный анализ, без опоры на внутренние оценки исходной презентации)
A3: Показатель | B3: Значение | C3: Источник / метод
A4: Рождений в РФ, 2024 | B4: ~1,22 млн чел. | C4: Росстат (оперативные данные по итогам 2024 г.)
A5: Суммарный коэффициент рождаемости (СКР), РФ | B5: ~1,4 | C5: Росстат, 2023–2024 гг.
A6: Инфертильность в мире | B6: ~15–17% пар | C6: ВОЗ (оценки по распространённости бесплодия)
A7: Циклы ВРТ в РФ в год | B7: ~120–130 тыс. | C7: Федеральный регистр ВРТ Минздрава РФ (публичные оценки 2022–2024 гг.); рост ~5–7%/год
A8: Доля циклов по ОМС | B8: ~50–60% | C8: Публичные заявления МЗ РФ о квотах ОМС на ВРТ
A9: Доля Москвы в циклах РФ | B9: ~20–25% | C9: Экспертная оценка: концентрация федеральных центров ВРТ и НМИЦ; ~25–30 тыс. циклов/год
A10: Средняя стоимость коммерческого цикла (Москва) | B10: 250–450 тыс. ₽ | C10: Открытые прайсы клиник (НМИЦ, коммерческие центры), 2024–2025 гг.
A11: Средняя стоимость цикла по ОМС (тариф) | B11: 130–200 тыс. ₽ | C11: Региональные тарифы ОМС на ВРТ (открытые данные ФОМС/рег. тарифы)
A12: Клинический рынок ВРТ РФ (TAM клин.) | B12: ~25–30 млрд ₽/год | C12: Расчёт: ~125 тыс. циклов × ~200 тыс. ₽ средневзвешенно (ОМС+коммерция)
A13: SAM — софт и аналитика для ВРТ (софт-часть от чека ~8–10%) | B13: ~2–3 млрд ₽/год | C13: Экспертная оценка доли ИТ/аналитики в стоимости цикла
A14: SOM VitaGen к 2030 (модель) | B14: 390 млн ₽/год | C14: Расчёт модели; ~13–17% SAM РФ + ранний APAC
... A21: Хайнань: льготный КН для поощряемых отраслей | B21: 15% | C21: Политика зоны свободной торговли Хайнань (СПК Госсовета КНР), в т.ч. высокие технологии/здравоохранение
A24: TAM / SAM / SOM (РФ + АТР)
A25: TAM РФ (клинический рынок ВРТ) | B25: 25–30 млрд ₽/год
A26: SAM РФ (софт/аналитика ВРТ) | B26: 2–3 млрд ₽/год
A27: SOM VitaGen РФ к 2030 | B27: 390 млн ₽/год (модель)
A28: TAM Китай/АТР (клинический) | B28: ~$15–20 млрд/год
A29: SAM Китай (софт/аналитика) | B29: ~$1–2 млрд/год (эксп. оценка)
A30: SOM VitaGen APAC к 2030 | B30: 35 млн ₽/год (ранний вход, пилотный масштаб)

Sheet Выручка
A1: ВЫРУЧКА по направлениям, млн ₽ (с коэффициентом сценария)
A3: Показатель | B3: Ед. | C3: 2026 | D3: 2027 | E3: 2028 | F3: 2029 | G3: 2030
A4: Клиническая подписка (SaaS + базовая аналитика) | C4: =Допущения!C11*Допущения!C18*Допущения!$C$5 -> 6.6 | D4: =Допущения!D11*Допущения!D18*Допущения!$C$5 -> 27.6 | E4: =Допущения!E11*Допущения!E18*Допущения!$C$5 -> 80 | F4: =Допущения!F11*Допущения!F18*Допущения!$C$5 -> 143 | G4: =Допущения!G11*Допущения!G18*Допущения!$C$5 -> 238
A5: Доп. модули (ниPGT-A, эндометрий, мужской геном, перинатология) | C5: =Допущения!C12*Допущения!C18*Допущения!$C$5 -> 0.45 | D5: =Допущения!D12*Допущения!D18*Допущения!$C$5 -> 4.2 | E5: =Допущения!E12*Допущения!E18*Допущения!$C$5 -> 19.2 | F5: =Допущения!F12*Допущения!F18*Допущения!$C$5 -> 44 | G5: =Допущения!G12*Допущения!G18*Допущения!$C$5 -> 85
A6: Матчинг донорство / суррогатное материнство | C6: =Допущения!C13*Допущения!C20*Допущения!$C$5 -> 0 | D6: =Допущения!D13*Допущения!D20*Допущения!$C$5 -> 1.44 | E6: =Допущения!E13*Допущения!E20*Допущения!$C$5 -> 4.5 | F6: =Допущения!F13*Допущения!F20*Допущения!$C$5 -> 8.1 | G6: =Допущения!G13*Допущения!G20*Допущения!$C$5 -> 12.6
A7: B2G-аналитика для регионов (CLBR / стоимость живорождения) | C7: =Допущения!C14*Допущения!C19*Допущения!$C$5 -> 0 | D7: =Допущения!D14*Допущения!D19*Допущения!$C$5 -> 4.5 | E7: =Допущения!E14*Допущения!E19*Допущения!$C$5 -> 10 | F7: =Допущения!F14*Допущения!F19*Допущения!$C$5 -> 16.5 | G7: =Допущения!G14*Допущения!G19*Допущения!$C$5 -> 30
A8: Международное направление: Китай (Хайнань) и АТР | C8: =Допущения!C15*Допущения!C21*Допущения!$C$5 -> 0 | D8: =Допущения!D15*Допущения!D21*Допущения!$C$5 -> 0 | E8: =Допущения!E15*Допущения!E21*Допущения!$C$5 -> 0 | F8: =Допущения!F15*Допущения!F21*Допущения!$C$5 -> 8.5 | G8: =Допущения!G15*Допущения!G21*Допущения!$C$5 -> 25.5
A10: ИТОГО ВЫРУЧКА | C10: =SUM(C4:C8) -> 7.05 | D10: =SUM(D4:D8) -> 37.74 | E10: =SUM(E4:E8) -> 113.7 | F10: =SUM(F4:F8) -> 220.1 | G10: =SUM(G4:G8) -> 391.1
A12: Проверка APAC: 2029–2030 — пилот и запуск WFOE в Хайнане (см. лист «Китай_АТР»)

Sheet Расходы
A1: ОПЕРАЦИОННЫЕ РАСХОДЫ, млн ₽ (с коэффициентом сценария)
A3: Показатель | B3: Ед. | C3: 2026 | D3: 2027 | E3: 2028 | F3: 2029 | G3: 2030
A4: ФОТ с отчислениями | C4: =Допущения!C24*Допущения!$C$6 -> 24 | D4: =Допущения!D24*Допущения!$C$6 -> 40 | E4: =Допущения!E24*Допущения!$C$6 -> 62 | F4: =Допущения!F24*Допущения!$C$6 -> 95 | G4: =Допущения!G24*Допущения!$C$6 -> 140
A5: НИОКР (подряды, данные) | C5: =Допущения!C25*Допущения!$C$6 -> 10 | D5: =Допущения!D25*Допущения!$C$6 -> 12 | E5: =Допущения!E25*Допущения!$C$6 -> 15 | F5: =Допущения!F25*Допущения!$C$6 -> 20 | G5: =Допущения!G25*Допущения!$C$6 -> 28
A6: Маркетинг и продажи | C6: =Допущения!C26*Допущения!$C$6 -> 2 | D6: =Допущения!D26*Допущения!$C$6 -> 5 | E6: =Допущения!E26*Допущения!$C$6 -> 10 | F6: =Допущения!F26*Допущения!$C$6 -> 16 | G6: =Допущения!G26*Допущения!$C$6 -> 24
A7: Инфраструктура / облако | C7: =Допущения!C27*Допущения!$C$6 -> 2 | D7: =Допущения!D27*Допущения!$C$6 -> 4 | E7: =Допущения!E27*Допущения!$C$6 -> 9 | F7: =Допущения!F27*Допущения!$C$6 -> 18 | G7: =Допущения!G27*Допущения!$C$6 -> 30
A8: Административные и юридические | C8: =Допущения!C28*Допущения!$C$6 -> 4 | D8: =Допущения!D28*Допущения!$C$6 -> 6 | E8: =Допущения!E28*Допущения!$C$6 -> 8 | F8: =Допущения!F28*Допущения!$C$6 -> 11 | G8: =Допущения!G28*Допущения!$C$6 -> 15
A9: Регуляторика РФ + NMPA | C9: =Допущения!C29*Допущения!$C$6 -> 4.5 | D9: =Допущения!D29*Допущения!$C$6 -> 3.5 | E9: =Допущения!E29*Допущения!$C$6 -> 2.5 | F9: =Допущения!F29*Допущения!$C$6 -> 7 | G9: =Допущения!G29*Допущения!$C$6 -> 8
A11: ИТОГО РАСХОДЫ | C11: =SUM(C4:C9) -> 46.5 | D11: =SUM(D4:D9) -> 70.5 | E11: =SUM(E4:E9) -> 106.5 | F11: =SUM(F4:F9) -> 167 | G11: =SUM(G4:G9) -> 245

Sheet PnL
A1: ОТЧЁТ О ПРИБЫЛЯХ И УБЫТКАХ (усиленный), млн ₽
A3: Показатель | B3: Ед. | C3: 2026 | D3: 2027 | E3: 2028 | F3: 2029 | G3: 2030
A4: Выручка | C4: =Выручка!C10 -> 7.05 | D4: =Выручка!D10 -> 37.74 | E4: =Выручка!E10 -> 113.7 | F4: =Выручка!F10 -> 220.1 | G4: =Выручка!G10 -> 391.1
A6: Операционные расходы | C6: =-Расходы!C11 -> -46.5 | D6: =-Расходы!D11 -> -70.5 | E6: =-Расходы!E11 -> -106.5 | F6: =-Расходы!F11 -> -167 | G6: =-Расходы!G11 -> -245
A8: EBITDA | C8: =C4+C6 -> -39.45 | D8: =D4+D6 -> -32.76 | E8: =E4+E6 -> 7.2 | F8: =F4+F6 -> 53.1 | G8: =G4+G6 -> 146.1
A9: EBITDA-маржа | C9: =IF(C4=0,0,C8/C4) -> -5.5957447 | D9: =IF(D4=0,0,D8/D4) -> -0.86804452 | E9: =IF(E4=0,0,E8/E4) -> 0.063324538 | F9: =IF(F4=0,0,F8/F4) -> 0.24125398 | G9: =IF(G4=0,0,G8/G4) -> 0.37356175
A11: Налог УСН «доходы» (5%) | C11: =-MAX(0,C8)*Допущения!C32/100 -> 0 | D11: =-MAX(0,D8)*Допущения!D32/100 -> 0 | E11: =-MAX(0,E8)*Допущения!E32/100 -> -0.36 | F11: =-MAX(0,F8)*Допущения!F32/100 -> -2.655 | G11: =-MAX(0,G8)*Допущения!G32/100 -> -7.305
A12: Чистая прибыль | C12: =C8+C11 -> -39.45 | D12: =D8+D11 -> -32.76 | E12: =E8+E11 -> 6.84 | F12: =F8+F11 -> 50.445 | G12: =G8+G11 -> 138.795
A13: Чистая маржа | C13: =IF(C4=0,0,C12/C4) -> -5.5957447 | D13: =IF(D4=0,0,D12/D4) -> -0.86804452 | E13: =IF(E4=0,0,E12/E4) -> 0.060158311 | F13: =IF(F4=0,0,F12/F4) -> 0.22919128 | G13: =IF(G4=0,0,G12/G4) -> 0.35488366

Sheet ДДС
A1: ОТЧЁТ О ДВИЖЕНИИ ДЕНЕЖНЫХ СРЕДСТВ (упрощённый), млн ₽
A3: Показатель | B3: Ед. | C3: 2026 | D3: 2027 | E3: 2028 | F3: 2029 | G3: 2030
A4: Остаток на начало года | C4: 0 | D4: =C11 -> 0.55 | E4: =D11 -> 20.79 | F4: =E11 -> 33.99 | G4: =F11 -> 91.09
A6: Операционный денежный поток (=EBITDA, прокси) | C6: =PnL!C8 -> -39.45 | D6: =PnL!D8 -> -32.76 | E6: =PnL!E8 -> 7.2 | F6: =PnL!F8 -> 53.1 | G6: =PnL!G8 -> 146.1
A7: Поступления: Раунд 1 (Seed) | C7: =Допущения!C33 -> 35 | D7: =Допущения!D33 -> 0 | E7: =Допущения!E33 -> 0 | F7: =Допущения!F33 -> 0 | G7: =Допущения!G33 -> 0
A8: Поступления: Раунд 2 (Series A) | C8: =Допущения!C34 -> 0 | D8: =Допущения!D34 -> 45 | E8: =Допущения!E34 -> 0 | F8: =Допущения!F34 -> 0 | G8: =Допущения!G34 -> 0
A9: Поступления: гранты (non-dilutive) | C9: =Допущения!C35 -> 5 | D9: =Допущения!D35 -> 8 | E9: =Допущения!E35 -> 6 | F9: =Допущения!F35 -> 4 | G9: =Допущения!G35 -> 2
A11: Остаток на конец года | C11: =C4+SUM(C6:C9) -> 0.55 | D11: =D4+SUM(D6:D9) -> 20.79 | E11: =E4+SUM(E6:E9) -> 33.99 | F11: =F4+SUM(F6:F9) -> 91.09 | G11: =G4+SUM(G6:G9) -> 239.19
A13: Комментарий: пик дефицита — конец 2027 г.; покрывается Раундами 1+2 (77,5 млн ₽) с резервом; выход в плюс — 2029 г.

Sheet Инвестор
A1: СДЕЛКА, CAP TABLE И ДОХОДНОСТЬ ИНВЕСТОРА
A3: Раунд 1 — Seed (2026)
A4: Pre-money (вкл. оценку ИС 45 млн ₽) | B4: =Допущения!C38 -> 110
A5: Сумма инвестиций | B5: =Допущения!C33 -> 35
A6: Post-money | B6: =B4+B5 -> 145
A7: Доля инвестора 1 | B7: =B5/B6 -> 0.24137931
A8: Формат | B8: Привилегированные акции, ликвидационная привилегия 1,5×
A10: Раунд 2 — Series A (2027)
A11: Pre-money | B11: =Допущения!C39 -> 280
A12: Сумма инвестиций | B12: =Допущения!D34 -> 45
A13: Post-money | B13: =B11+B12 -> 325
A14: Доля инвестора 2 | B14: =B12/B13 -> 0.13846154
A16: CAP TABLE после Раунда 2 (доля в капитале)
A17: Участник | B17: Доля
A18: Основатель / ООО «МедТехПрима» (обыкновенные) | B18: =(1-B7)*(1-B14)*0.85/0.88 -> 0.63129973
A19: Опционный пул для команды (12% пост-инвест, упрощённо) | B19: =(1-B7)*(1-B14)*0.12/0.88 -> 0.089124668
A20: Инвестор 1 (привилегированные, Раунд 1) | B20: =B7*(1-B14) -> 0.20795756
A21: Инвестор 2 (привилегированные, Раунд 2) | B21: =B14 -> 0.13846154
A22: ИТОГО | B22: =B18+B19+B20+B21 -> 1.0668435
A24: ВЫХОД (2031, стратегический покупатель)
A25: EBITDA 2031 | B25: =Допущения!C40 -> 180
A26: Множитель | B26: =Допущения!C41 -> 7.5
A27: Стоимость компании при выходе | B27: =B25*B26 -> 1350
A28: Выплата инвестору 1 (пропорционально доле) | B28: =B27*B20 -> 280.74271
A29: Выплата инвестору 2 (пропорционально доле) | B29: =B27*B21 -> 186.92308
A30: Кратность для инвестора 1 | B30: =B28/B5 -> 8.0212202
A31: Кратность для инвестора 2 | B31: =B29/B12 -> 4.1538462
A33: ДЕНЕЖНЫЕ ПОТОКИ ИНВЕСТОРА И ДОХОДНОСТЬ (годовые)
A34: Год | B34: Инвестор 1 | C34: Инвестор 2
A35: 2026 | B35: =-Допущения!C33 -> -35 | C35: 0
A36: 2027 | B36: 0 | C36: =-Допущения!D34 -> -45
A37: 2028 | B37: 0 | C37: 0
A38: 2029 | B38: 0 | C38: 0
A39: 2030 | B39: 0 | C39: 0
A40: 2031 | B40: =B28 -> 280.74271 | C40: =B29 -> 186.92308
A42: IRR инвестора 1 (2026→2031) | B42: =IRR(B35:B40) -> 0.51651981
A43: IRR инвестора 2 (2027→2031) | B43: =IRR(C36:C40) -> 0.42761993
A44: NPV инвестора 1 при ставке 25% | B44: =NPV(Допущения!C42,B35:B40) -> 45.595016
A45: Срок окупаемости инвестора 1 | B45: к 2031 (выход); операционная безубыточность проекта — 2029
A47: ЧУВСТВИТЕЛЬНОСТЬ: цена выхода (множитель EBITDA 2031 = 180 млн ₽)
...

Sheet ИС_Оценка
A1: ИНТЕЛЛЕКТУАЛЬНАЯ СОБСТВЕННОСТЬ (РИДы) И ЕЁ ОЦЕНКА — вклад в стоимость компании
A3: № | B3: РИД / объект | C3: Статус | D3: Накопленные затраты, млн ₽ | E3: Рыночная оценка, млн ₽ | F3: Комментарий
A4: 1 | B4: Свидетельство о включении в реестр РИД №1440-028-537 от 30.03.2026 (алгоритм/программа прогноза) | C4: Получено | D4: 8 | E4: 12–18 | F4: Правообладатель на старте — Петрушина М.В./МедТехПрима; планируется передача в АО «ВИТА ГЕН АИ» вкладом в УК
A5: 2 | B5: ПОЭВМ «VitaGen-AI Core» — мультимодальная платформа (5 уровней данных) | C5: Разработка / подача в ЕРИР 2026 | D5: 14 | E5: 20–28 | F5: Ключевой актив; эксклюзивная лицензия или вклад в УК
A6: 3 | B6: ПОЭВМ модулей: эндометрий, niPGT-A, мужской геном, перинатальные прогнозы | C6: План: заявки 2027–2028 | D6: 9 | E6: 12–18 | F6: Расширение линейки — рост ARPU
A7: 4 | B7: Патентные заявки на изобретения: способ прогноза с интеграцией DFI; иммунный матчинг KIR/HLA-C | C7: План: подача 2026–2027 | D7: 6 | E7: 10–15 | F7: Прорывные компоненты; патентная защита повышает barrier to entry
A8: 5 | B8: Know-how: обезличенный клинический датасет, методологии аннотации, чек-листы готовности данных | C8: Формируется в пилоте | D8: 5 | E8: 8–12 | F8: Датасет — стратегический актив (защита: 152-ФЗ, договоры с клиниками)
A9: 6 | B9: Товарный знак VitaGen | C9: Заявка | D9: 0.5 | E9: 1–2 | F9: Бренд для B2B/B2G и экспорта
C11: ИТОГО | D11: =SUM(D4:D9) -> 42.5 | E11: 53–93 (диапазон)
A13: МЕТОДЫ ОЦЕНКИ (три подхода)
A14: Затратный подход | B14: Накопленные затраты на НИОКР + амортизация риска неуспеха: ~40–45 млн ₽
A15: Рыночный подход (сделки лицензирования medtech-AI) | B15: Роялти 5–8% от выручки, дисконтирование потоков: ~55–75 млн ₽
A16: Договорной / доходный (DCF доли ИС в стоимости проекта) | B16: Доля ИС в стоимости проекта 30–40%: ~45–60 млн ₽
A17: Принятая к вкладу в УК оценка (консервативная) | B17: 45 млн ₽ — по отчёту независимого оценщика (обязателен: ст. 34 ФЗ «Об АО», 273-ФЗ «Об оценочной деятельности»)
A19: Вклад ИС в АО: МедТехПрима вносит РИДы в УК АО «ВИТА ГЕН АИ» по оценке 45 млн ₽ → доля холдинга в УК до раундов. Инвестор получает гарантии: ИС принадлежит проектной компании (не холдингу), эксклюзивно, без обременений.

Sheet Китай_АТР
A1: МЕЖДУНАРОДНОЕ НАПРАВЛЕНИЕ: КИТАЙ (ХАЙНАНЬ) И АЗИАТСКО-ТИХООКЕАНСКИЙ РЫНОК
A3: Элемент | B3: Содержание
A4: Юридическая форма | B4: VitaGen AI (Hainan) Co., Ltd — wholly foreign-owned enterprise (WFOE) в зоне свободной торговли Хайнань; опционально промежуточный холд-ко в Гонконге для структурирования
A5: Зона/режим | B5: Хайнаньская зона свободной торговли (политика СПК Госсовета КНР): льготный корпоративный налог 15% для отраслей по списку поощряемых (высокие технологии, здравоохранение); пилотная зона Боао Лэчэн — упрощённый доступ инновационных медизделий
A6: Модель входа | B6: Лицензия ПО + revenue share с клиниками-партнёрами/дистрибьютором; опционально JV с местной medtech/лабораторией на позднем этапе
A7: Регуляторика | B7: NMPA: регистрация ПО как медицинского изделия II класса (12–18 мес.); в Боао Лэчэн — пилотный режим допуска инновационных устройств
A8: Данные (PIPL) | B8: Геномные и персональные данные пациентов не покидают КНР: локальное размещение модели (облако КНР), обучение/дообучение на локальных данных; экспорт только агрегированных метрик
A9: Команда | B9: 2029: country manager + регуляторик; 2030: продажи/партнёрства (4–6 человек на старте)
A10: Этапы | B10: 2028 — gap-анализ NMPA, поиск партнёров; 2029 — регистрация WFOE, 1–2 пилотных партнёра, выручка ~10 млн ₽; 2030 — NMPA-файлинг/регистрация, 4–6 партнёров, выручка ~35 млн ₽
A11: Выручка в модели | B11: 2029: 10 млн ₽; 2030: 35 млн ₽ (лист «Выручка», строка «Международное направление»); далее драйвер роста пост-2030
A12: Пайплайн АТР после Китая | B12: Индия (~250 тыс. циклов/год, отраслевые оценки), Япония, Южная Корея, Сингапур, Индонезия, Таиланд — приоритизация после отработки китайского play book
A13: Риски | B13: Регуляторные задержки NMPA; геополитика; конкуренция локальных игроков; PIPL-требования; конвертация/репатриация прибыли (через HK/дивиденды)
A14: Налоговая оптимизация | B14: Хайнань 15% КН; при двустороннем соглашении РФ-КНР — снижение удержания; реинвестирование в рост АТР
